<?xml version="1.0" ?>
<!--
  Gazebo ROS depth camera plugin demo

  Try for example:

  * Try listening to camera info at
      `/demo_cam/mycamera/raw_cam_info_demo`
      `/demo_cam/mycamera/depth_cam_info_demo`

  * Launch RViz
  * Visualize Raw Images from `/demo_cam/mycamera/image_demo`
  * Visualize Depth Images from `/demo_cam/mycamera/depth_demo`
  * Visualize Point Cloud from `/demo_cam/mycamera/points_demo`

-->
<sdf version="1.6">
  <world name="default">

    <include>
      <uri>model://sun</uri>
    </include>

    <include>
      <uri>model://ground_plane</uri>
    </include>
    
    <include>
      <uri>model://ridge</uri>
      <name>"ridge01"</name>
      <pose>0 5 0 0 0 0</pose>
    </include>
    <include>
      <uri>model://ridge</uri>
      <name>"ridge02"</name>
      <pose>0 3 0 0 0 0</pose>
    </include>
    <include>
      <uri>model://ridge</uri>
      <name>"ridge03"</name>
      <pose>0 1 0 0 0 0</pose>
    </include>
    <include>
      <uri>model://ridge</uri>
      <name>"ridge04"</name>
      <pose>0 -1 0 0 0</pose>
    </include>
    <include>
      <uri>model://ridge</uri>
      <name>"ridge05"</name>
      <pose>0 -3 0 0 0 0</pose>
    </include>
    <include>
      <uri>model://ridge</uri>
      <name>"ridge06"</name>
      <pose>0 -5 0 0 0 0</pose>
    </include>
    
    
    <include>
      <uri>model://weed</uri>
      <name>"weed01"</name>
      <pose>0.8 0.1 0 0 0 0</pose>
    </include>
    <include>
      <uri>model://weed</uri>
      <name>"weed02"</name>
      <pose>1.2 -0.25 0 0 0 0.5</pose>
    </include>
    <include>
      <uri>model://weed</uri>
      <name>"weed03"</name>
      <pose>1.5 -0.05 0 0 0 0.5</pose>
    </include>
    <include>
      <uri>model://weed</uri>
      <name>"weed04"</name>
      <pose>2.0 -0.12 0 0 0 0.5</pose>
    </include>
    <include>
      <uri>model://weed</uri>
      <name>"weed05"</name>
      <pose>2.4 0.21 0 0 0 0.5</pose>
    </include>
    <include>
      <uri>model://weed</uri>
      <name>"weed06"</name>
      <pose>3.0 0.31 0 0 0 0.5</pose>
    </include>
    <include>
      <uri>model://weed</uri>
      <name>"weed07"</name>
      <pose>3.4 0.04 0 0 0 0.5</pose>
    </include>
    <include>
      <uri>model://weed</uri>
      <name>"weed08"</name>
      <pose>4.0 -0.32 0 0 0 0.5</pose>
    </include>
    <include>
      <uri>model://weed</uri>
      <name>"weed09"</name>
      <pose>4.2 0.28 0 0 0 0.5</pose>
    </include>
    <include>
      <uri>model://weed</uri>
      <name>"weed10"</name>
      <pose>4.8 0.12 0 0 0 0.5</pose>
    </include>
    <include>
      <uri>model://weed</uri>
      <name>"weed11"</name>
      <pose>5.2 0.29 0 0 0 0.5</pose>
    </include>
    <include>
      <uri>model://weed</uri>
      <name>"weed12"</name>
      <pose>5.8 -0.18 0 0 0 0.5</pose>
    </include>

    <model name='vehicle'>
      <pose>0 0 0.0 0 -0 0</pose>

      <link name='base_link'>
        <pose>0.0 0.0 0.65 0 -0 0</pose>
        <visual name='visual'>
          <geometry>
            <box>
              <size>0.7 0.5 0.7</size>
            </box>
          </geometry>
        </visual>
      </link>

      <link name='left_wheel'>
        <pose>0.25 0.25 0.1 -1.5707 0 0</pose>
        <inertial>
          <mass>2</mass>
          <inertia>
            <ixx>0.145833</ixx>
            <ixy>0</ixy>
            <ixz>0</ixz>
            <iyy>0.145833</iyy>
            <iyz>0</iyz>
            <izz>0.125</izz>
          </inertia>
        </inertial>
        <visual name='visual'>
          <geometry>
            <sphere>
              <radius>0.1</radius>
            </sphere>
          </geometry>
        </visual>
        <collision name='collision'>
          <geometry>
            <sphere>
              <radius>0.1</radius>
            </sphere>
          </geometry>
          <surface>
            <friction>
              <ode>
                <mu>1</mu>
                <mu2>1</mu2>
                <slip1>0</slip1>
                <slip2>0</slip2>
              </ode>
            </friction>
            <contact>
              <ode>
                <soft_cfm>0</soft_cfm>
                <soft_erp>0.2</soft_erp>
                <kp>1e+13</kp>
                <kd>1</kd>
                <max_vel>0.01</max_vel>
                <min_depth>0.01</min_depth>
              </ode>
            </contact>
          </surface>
        </collision>
      </link>

      <link name='right_wheel'>
        <pose>0.25 -0.25 0.1 -1.5707 0 0</pose>
        <inertial>
          <mass>2</mass>
          <inertia>
            <ixx>0.145833</ixx>
            <ixy>0</ixy>
            <ixz>0</ixz>
            <iyy>0.145833</iyy>
            <iyz>0</iyz>
            <izz>0.125</izz>
          </inertia>
        </inertial>
        <visual name='visual'>
          <geometry>
            <sphere>
              <radius>0.1</radius>
            </sphere>
          </geometry>
        </visual>
        <collision name='collision'>
          <geometry>
            <sphere>
              <radius>0.1</radius>
            </sphere>
          </geometry>
          <surface>
            <friction>
              <ode>
                <mu>1</mu>
                <mu2>1</mu2>
                <slip1>0</slip1>
                <slip2>0</slip2>
              </ode>
            </friction>
            <contact>
              <ode>
                <soft_cfm>0</soft_cfm>
                <soft_erp>0.2</soft_erp>
                <kp>1e+13</kp>
                <kd>1</kd>
                <max_vel>0.01</max_vel>
                <min_depth>0.01</min_depth>
              </ode>
            </contact>
          </surface>
        </collision>
      </link>

      <link name='caster'>
        <pose>-0.25 0 0.1 0 -0 0</pose>
        <inertial>
          <mass>1</mass>
          <inertia>
            <ixx>0.1</ixx>
            <ixy>0</ixy>
            <ixz>0</ixz>
            <iyy>0.1</iyy>
            <iyz>0</iyz>
            <izz>0.1</izz>
          </inertia>
        </inertial>
        <visual name='visual'>
          <geometry>
            <sphere>
              <radius>0.1</radius>
            </sphere>
          </geometry>
        </visual>
        <collision name='collision'>
          <geometry>
            <sphere>
              <radius>0.1</radius>
            </sphere>
          </geometry>
        </collision>
      </link>

      <joint name='left_wheel_joint' type='revolute'>
        <parent>base_link</parent>
        <child>left_wheel</child>
        <axis>
          <xyz>0 0 1</xyz>
          <limit>
            <lower>-1.79769e+308</lower>
            <upper>1.79769e+308</upper>
          </limit>
        </axis>
      </joint>

      <joint name='right_wheel_joint' type='revolute'>
        <parent>base_link</parent>
        <child>right_wheel</child>
        <axis>
          <xyz>0 0 1</xyz>
          <limit>
            <lower>-1.79769e+308</lower>
            <upper>1.79769e+308</upper>
          </limit>
        </axis>
      </joint>

      <joint name='caster_wheel' type='ball'>
        <parent>base_link</parent>
        <child>caster</child>
      </joint>

      <plugin name='diff_drive' filename='libgazebo_ros_diff_drive.so'>

        <ros>
          <namespace>/agribot</namespace>
          <remapping>cmd_vel:=cmd_vel</remapping>
          <remapping>odom:=odom</remapping>
        </ros>

        <!-- wheels -->
        <left_joint>left_wheel_joint</left_joint>
        <right_joint>right_wheel_joint</right_joint>

        <!-- kinematics -->
        <wheel_separation>1.25</wheel_separation>
        <wheel_diameter>0.6</wheel_diameter>

        <!-- limits -->
        <max_wheel_torque>20</max_wheel_torque>
        <max_wheel_acceleration>1.0</max_wheel_acceleration>

        <!-- output -->
        <publish_odom>true</publish_odom>
        <publish_odom_tf>true</publish_odom_tf>
        <publish_wheel_tf>true</publish_wheel_tf>

        <odometry_frame>odom</odometry_frame>
        <robot_base_frame>base_link</robot_base_frame>

      </plugin>
      
      
      <link name="rs_front">
        <pose>0.45 0 1.5 0 0.523 0</pose>
        <visual name="visual">
          <geometry>
            <mesh>
              <uri>model://kinect/meshes/kinect.dae</uri>
            </mesh>
          </geometry>
        </visual>
        <sensor type="depth" name="camera1">
          <update_rate>30</update_rate>
          <visualize>false</visualize>
          <camera>
            <!-- HFOV = 2*math.atan( width / fx / 2.0 ) -->
            <horizontal_fov>0.9546805929177397</horizontal_fov>
            <image>
              <width>640</width>
              <height>480</height>
              <format>B8G8R8</format>
            </image>
            <depth_camera>
            </depth_camera>
            <clip>
              <near>0.02</near>
              <far>300</far>
            </clip>
            <noise>
              <type>gaussian</type>
              <!-- Noise is sampled independently per pixel on each frame.
                   That pixel's noise value is added to each of its color
                   channels, which at that point lie in the range [0,1]. -->
              <mean>0.0</mean>
              <stddev>0.007</stddev>
            </noise>
          </camera>
          <plugin name="camera_controller" filename="libgazebo_ros_camera.so">
            <ros>
              <namespace>/agribot</namespace>

              <!-- topics need to be prefixed with camera_name for remapping -->
              <remapping>mycamera/image_raw:=camera/rs_front/color/image_raw</remapping>
              <remapping>mycamera/depth/image_raw:=camera/rs_front/aligned_depth_to_color/image_raw</remapping>
              <remapping>mycamera/camera_info:=camera/rs_front/color/camera_info</remapping>
              <remapping>mycamera/depth/camera_info:=camera/rs_front/aligned_depth_to_color/camera_info</remapping>
              <!-- <remapping>mycamera/points:=camera/rs_front/points /camera/depth/color/points</remapping>
              -->
              <remapping>mycamera/points:=/camera/depth/color/points</remapping>
            </ros>

            <!-- omit camera_name to default to sensor name -->
            <camera_name>mycamera</camera_name>

            <!-- frame_name>omit so it defaults to link name</frame_name-->

            <min_depth>0.1</min_depth>
            <max_depth>500</max_depth>
            
            <!-- https://github.com/ros-simulation/gazebo_ros_pkgs/blob/eloquent/gazebo_plugins/src/gazebo_ros_camera.cpp -->
            <cx>320.40997314453125</cx>
            <cy>242.66018676757812</cy>
          </plugin>
        </sensor>
      </link>
      
      <joint name="camera_joint" type="fixed">
        <parent>base_link</parent>
        <child>rs_front</child>
      </joint>

<!--      
      <link name='camera_weed1'>
        <pose>0.6 0 1.0 0 1.27 0</pose>
        <visual name='visual'>
          <geometry>
            <box>
              <size>0.1 0.1 0.1</size>
            </box>
          </geometry>
        </visual>
        <sensor name='camera_weed1' type='camera'>
          <camera>
            <horizontal_fov>1.047</horizontal_fov>
            <image>
              <width>640</width>
              <height>480</height>
            </image>
            <clip>
              <near>0.1</near>
              <far>100</far>
            </clip>
          </camera>
          
          <plugin name="camera_controller" filename="libgazebo_ros_camera.so">
            <ros>
              <namespace>/agribot</namespace>
              <remapping>weed1/image_raw:=camera/weed1/image_raw</remapping>
              <remapping>weed1/camera_info:=camera/weed1/camera_info</remapping>
            </ros>
-->
            <!-- omit camera_name to default to sensor name -->
<!--
            <camera_name>weed1</camera_name>
          </plugin>
          <always_on>1</always_on>
          <update_rate>30</update_rate>
        </sensor>
      </link>

      <joint name="camera_weed1_joint" type="fixed">
        <parent>base_link</parent>
        <child>camera_weed1</child>
      </joint>
-->
      <!-- rear camera -->
<!--
      <link name='camera_rear'>
        <pose>-0.7 0 1.0 0 1.37 0</pose>
        <visual name='visual'>
          <geometry>
            <box>
              <size>0.1 0.1 0.1</size>
            </box>
          </geometry>
        </visual>
        <sensor name='camera_rear' type='camera'>
          <camera>
            <horizontal_fov>1.047</horizontal_fov>
            <image>
              <width>640</width>
              <height>480</height>
            </image>
            <clip>
              <near>0.1</near>
              <far>100</far>
            </clip>
          </camera>
          
          <plugin name="camera_controller" filename="libgazebo_ros_camera.so">
            <ros>
              <namespace>/agribot</namespace>
              <remapping>rear/image_raw:=camera/rear/image_raw</remapping>
              <remapping>rear/camera_info:=camera/rear/camera_info</remapping>
            </ros>
-->
            <!-- omit camera_name to default to sensor name -->
<!--
            <camera_name>rear</camera_name>
          </plugin>
          <always_on>1</always_on>
          <update_rate>30</update_rate>
        </sensor>
      </link>

      <joint name="camera_rear_joint" type="fixed">
        <parent>base_link</parent>
        <child>camera_rear</child>
      </joint>
-->
    </model>


  </world>
</sdf>
